Workbook

Sheet Drop down menu
A1: Dropdown menu
A3: Customer | B3: Product category | C3: Subcategory | D3: Business category | E3: Business unit | F3: Stage | G3: Closure | H3: Confidence level | I3: Sales | J3: Presales
A4: MSIL (4W) | B4: IVI | C4: DA | D4: Line-fit | E4: MPC | F4: A | G4: TBC | H4: High | I4: Ashish | J4: Rachit
A5: Hyundai / Kia (4W) | B5: Sound | C5: IVI | D5: End-of-Line | E5: MCC | F5: B | G5: 45809 | H5: Mid | I5: Gaurav | J5: Haseeb
A6: Tata PV (4W) | B6: Smartcam | C6: CDC | D6: DOP | E6: MAC | F6: C | G6: 45839 | H6: Low | I6: Parvez
A7: Mahindra (4W) | B7: Connectivity | C7: HPC | D7: POC - Paid | E7: MSC | F7: D | G7: 45870 | H7: Dropped | I7: KG/PA
A8: Honda (4W) | B8: Other MAC | C8: Spks. | D8: POC - Free | E8: TBC | F8: E | G8: 45901 | H8: On hold
A9: MG Motor (4W) | C9: Amps. | D9: TBC | F9: F | G9: 45931 | H9: Lost
A10: Toyota (4W) | C10: Spk + Amp | F10: SECURED | G10: 45962 | H10: Secured
A11: VW / Skoda (4W) | C11: Dashcam | F11: O (L) | G11: 45992
A12: Stellantis (4W) | C12: Digital mirror | F12: O (H) | G12: 46023
A13: Renault (4W) | C13: 360-deg. camera | F13: O (D) | G13: 46054
A14: Audi (4W) | C14: Thermal camera | G14: 46082
A15: Daimler (4W) | C15: Dongle | G15: 46113
A16: Tata CV (CV) | C16: TCU | G16: 46143
A17: Ashok Leyland (CV) - Truck | C17: WLC | G17: 46174
A18: Eicher/Volvo (CV) | C18: USB port | G18: 46204
A19: UD Trucks (CV) | C19: DMS | G19: 46235
A20: Force Motors (CV) | C20: Cluster (2W) | G20: 46266
A21: Switch Mobility (CV) | C21: RVC | G21: 46296
A22: Hero Motocorp (2W) | C22: RVC with Display | G22: 46327
A23: Bajaj (2W) | G23: 46357
A24: TVS (2W) | G24: 46388
A25: Royal Enfield (2W) | G25: 46419
A26: Suzuki (2W) | G26: 46447
A27: Ather (2W) | G27: 46478
A28: VGT (4W) | G28: 46508
A29: Hinduja Tech (4W) | G29: 46539
A30: Daimler (CV) | G30: 46569
A31: Isuzu (CV) | G31: 46600
A32: Tech Mahindra (4W) | G32: 46631
A33: Vinfast (4W) | G33: 46661
A34: JCB (CV) | G34: 46692
A35: Isuzu (PV) | G35: 46722
A36: Peec Mobility (4W) | G36: Dropped
A37: Toyota Tadme (4W) | G37: On hold
A38: Stellantis (3W) | G38: Lost
A39: Nissan (4W) | G39: Secured
A40: FIAT
A41: PACCAR
...

Sheet Opportunity stage
A1: Opportunity stages
A3: Deal stage | B3: Deal classification | C3: Deal status | D3: Winning probability
A4: A | B4: Before Lead | C4: Planning | D4: 0
A5: B | B5: Before Lead | C5: Lead Generation | D5: 0.35
A6: C | B6: Lead | C6: Lead Qualification | D6: 0.5
A7: D | B7: Lead | C7: Supplier Qualification | D7: 0.5
A8: E | B8: RFQ | C8: Opportunity | D8: 0.5
A9: F | B9: RFQ | C9: Negotiation | D9: 0.75
A10: SECURED | B10: Win | C10: Closing | D10: 1
A11: O (L) | B11: Lost | C11: Other | D11: 0
A12: O (H) | B12: Hold | C12: Other | D12: 0
A13: O (D) | B13: Dropped | C13: Other | D13: 0

Sheet OE Opportunities
A1: OE Opportunities | K1: Formula | R1: Formula
H2: Lead | I2: Lead | N2: Contract | P2: Estimated | Q2: Estimated | R2: 84.21
A3: Sr. no. | B3: Customer | C3: Description | D3: Business Unit | E3: Product category | F3: Product subcategory | G3: Business category | H3: PIN Sales | I3: PIN Presales | J3: Deal stage | K3: Deal classification | L3: Deal status | M3: Winning probability | N3: Estimated closure date | O3: Confidence level | P3: Lifetime volume | Q3: Unit price (INR) | R3: Unit price (USD) | S3: TCV (USD Mln.) | T3: Comments | U3: PMS | V3: Remarks
A4: 1 | B4: Royal Enfield | C4: Navigation Display unit | D4: MAC | E4: Other MAC | F4: Cluster (2W) | G4: Line-fit | H4: Gaurav | I4: Haseeb | J4: O (H) | K4: =VLOOKUP(J4,'Opportunity stage'!A$3:D$13,2,0) -> Hold | L4: =VLOOKUP(J4,'Opportunity stage'!A$3:D$13,3,0) -> Other | M4: =VLOOKUP(J4,'Opportunity stage'!A$3:D$13,4,0) -> 0 | N4: TBC | O4: Low | P4: 900000 | Q4: 1200 | R4: =Q4/$R$2 -> 14.250089 | S4: =(P4*R4)/1000000 -> 12.82508 | T4: On hold due to bandwidth issue. | U4: N
A5: 2 | B5: Ashok Leyland (CV) | C5: 360-deg. camera solution (4-camera with 6" screen) | D5: MAC | E5: Smartcam | F5: 360-deg. camera | G5: POC - Paid | H5: Gaurav | I5: Haseeb | J5: O (H) | K5: =VLOOKUP(J5,'Opportunity stage'!A$3:D$13,2,0) -> Hold | L5: =VLOOKUP(J5,'Opportunity stage'!A$3:D$13,3,0) -> Other | M5: =VLOOKUP(J5,'Opportunity stage'!A$3:D$13,4,0) -> 0 | N5: TBC | O5: Low | P5: 1 | Q5: 22000 | R5: =Q5/$R$2 -> 261.25163 | S5: =(P5*R5)/1000000 -> 0.00026125163 | T5: ADAS is priority for AL at this stage, once the feature is rolled out then 360 feature will be explored | U5: N
A6: 3 | B6: Honda (4W) | C6: 360-deg. camera solution | D6: MAC | E6: Smartcam | F6: 360-deg. camera | G6: Line-fit | H6: Ashish | I6: Rachit | J6: O (H) | K6: =VLOOKUP(J6,'Opportunity stage'!A$3:D$13,2,0) -> Hold | L6: =VLOOKUP(J6,'Opportunity stage'!A$3:D$13,3,0) -> Other | M6: =VLOOKUP(J6,'Opportunity stage'!A$3:D$13,4,0) -> 0 | N6: TBC | O6: Low | P6: =156000*0.3 -> 46800 | Q6: 13000 | R6: =Q6/$R$2 -> 154.37596 | S6: =(P6*R6)/1000000 -> 7.2247952 | T6: On-hold from Honda | U6: N
A7: 4 | B7: Honda (4W) | C7: USB Charger (A-Type/C-Type) (15W, 45W, 65W) | D7: MAC | E7: Other MAC | F7: USB port | G7: Line-fit | H7: Ashish | I7: Rachit | J7: O (H) | K7: =VLOOKUP(J7,'Opportunity stage'!A$3:D$13,2,0) -> Hold | L7: =VLOOKUP(J7,'Opportunity stage'!A$3:D$13,3,0) -> Other | M7: =VLOOKUP(J7,'Opportunity stage'!A$3:D$13,4,0) -> 0 | N7: TBC | O7: Mid | P7: =156000*0.5 -> 78000 | Q7: =25*85 -> 2125 | R7: =Q7/$R$2 -> 25.234533 | S7: =(P7*R7)/1000000 -> 1.9682936 | T7: Honda will release RFQ after vendor-code-creation | U7: N
A8: 5 | B8: Mahindra (4W) | C8: Branded Audio for U171 (Bolero Sports) - 10-spk | D8: MPC | E8: Sound | F8: Spk + Amp | G8: Line-fit | H8: Parvez | I8: Rachit | J8: O (L) | K8: Lost | L8: Lost | M8: Lost | N8: 45901 | O8: Lost | P8: 120000 | Q8: 13000 | R8: =Q8/$R$2 -> 154.37596 | S8: =(P8*R8)/1000000 -> 18.525116 | T8: Lost to Sony
A9: 6 | B9: Mahindra (4W) | C9: Branded Audio for Z115 (Scorpio N Refresh) - 12-spk | D9: MPC | E9: Sound | F9: Spk + Amp | G9: Line-fit | H9: Parvez | I9: Rachit | J9: O (L) | K9: =VLOOKUP(J9,'Opportunity stage'!A$3:D$13,2,0) -> Lost | L9: =VLOOKUP(J9,'Opportunity stage'!A$3:D$13,3,0) -> Other | M9: =VLOOKUP(J9,'Opportunity stage'!A$3:D$13,4,0) -> 0 | N9: 45992 | O9: Lost | P9: 439000 | Q9: 15000 | R9: =Q9/$R$2 -> 178.12611 | S9: =(P9*R9)/1000000 -> 78.197364 | T9: Lost to Harman | U9: Y
A10: 7 | B10: Mahindra (4W) | C10: Wirless Charger MPP Profile Qi 2.1 | D10: MAC | E10: Other MAC | F10: WLC | G10: Line-fit | H10: Gaurav | I10: Haseeb | J10: E | K10: =VLOOKUP(J10,'Opportunity stage'!A$3:D$13,2,0) -> RFQ | L10: =VLOOKUP(J10,'Opportunity stage'!A$3:D$13,3,0) -> Opportunity | M10: =VLOOKUP(J10,'Opportunity stage'!A$3:D$13,4,0) -> 0.5 | N10: 46082 | O10: High | P10: 1000000 | Q10: 1900 | R10: =Q10/$R$2 -> 22.562641 | S10: =(P10*R10)/1000000 -> 22.562641 | T10: RFQ received, TSO prpeparation in progress | U10: N
A11: 8 | B11: Mahindra (4W) | C11: Branded Audio for D101 (Thar Sport) - 10-spk | D11: MPC | E11: Sound | F11: Spk + Amp | G11: Line-fit | H11: Parvez | I11: Rachit | J11: O (L) | K11: =VLOOKUP(J11,'Opportunity stage'!A$3:D$13,2,0) -> Lost | L11: =VLOOKUP(J11,'Opportunity stage'!A$3:D$13,3,0) -> Other | M11: =VLOOKUP(J11,'Opportunity stage'!A$3:D$13,4,0) -> 0 | N11: 46082 | O11: Low | P11: 496056 | Q11: 13500 | R11: =Q11/$R$2 -> 160.3135 | S11: =(P11*R11)/1000000 -> 79.524475 | T11: Lost to Sony. | U11: Y
A12: 9 | B12: Mahindra (4W) | C12: USB Port - Type A/C (60W + 20W) | D12: MAC | E12: Other MAC | F12: USB port | G12: Line-fit | H12: Gaurav | I12: Haseeb | J12: B | K12: =VLOOKUP(J12,'Opportunity stage'!A$3:D$13,2,0) -> Before Lead | L12: =VLOOKUP(J12,'Opportunity stage'!A$3:D$13,3,0) -> Lead Generation | M12: =VLOOKUP(J12,'Opportunity stage'!A$3:D$13,4,0) -> 0.35 | N12: 46266 | O12: Low | P12: 208000 | Q12: 400 | R12: =Q12/$R$2 -> 4.7500297 | S12: =(P12*R12)/1000000 -> 0.98800618 | T12: Awaiting RFQ from M&M | U12: N
A13: 10 | B13: MSIL (4W) | C13: Entry DA | D13: MPC | E13: IVI | F13: DA | G13: Line-fit | H13: Ashish | I13: Rachit | J13: O (L) | K13: =VLOOKUP(J13,'Opportunity stage'!A$3:D$13,2,0) -> Lost | L13: =VLOOKUP(J13,'Opportunity stage'!A$3:D$13,3,0) -> Other | M13: 0.2 | N13: 45992 | O13: Low | P13: 1200000 | Q13: 7500 | R13: =Q13/$R$2 -> 89.063057 | S13: =(P13*R13)/1000000 -> 106.87567 | U13: Y
A14: 11 | B14: MSIL (4W) | C14: Dashcam solutions | D14: MAC | E14: Smartcam | F14: Dashcam | G14: Line-fit | H14: Ashish | I14: Rachit | J14: D | K14: =VLOOKUP(J14,'Opportunity stage'!A$3:D$13,2,0) -> Lead | L14: =VLOOKUP(J14,'Opportunity stage'!A$3:D$13,3,0) -> Supplier Qualification | M14: =VLOOKUP(J14,'Opportunity stage'!A$3:D$13,4,0) -> 0.5 | N14: 46357 | O14: Mid | P14: 732000 | Q14: 4000 | R14: =Q14/$R$2 -> 47.500297 | S14: =(P14*R14)/1000000 -> 34.770217 | U14: N
A15: 12 | B15: MSIL (4W) | C15: Premium Sound (4+2) | D15: MPC | E15: Sound | F15: Spks. | G15: Line-fit | H15: Ashish | I15: Rachit | J15: O (L) | K15: =VLOOKUP(J15,'Opportunity stage'!A$3:D$13,2,0) -> Lost | L15: =VLOOKUP(J15,'Opportunity stage'!A$3:D$13,3,0) -> Other | M15: 0.25 | N15: 45992 | O15: Low | P15: =85000*5 -> 425000 | Q15: 2000 | R15: =Q15/$R$2 -> 23.750148 | S15: =(P15*R15)/1000000 -> 10.093813 | U15: Y
A16: 13 | B16: MSIL (4W) | C16: Premium Sound (4+2+1+1) | D16: MPC | E16: Sound | F16: Spks. | G16: Line-fit | H16: Ashish | I16: Rachit | J16: O (L) | K16: =VLOOKUP(J16,'Opportunity stage'!A$3:D$13,2,0) -> Lost | L16: =VLOOKUP(J16,'Opportunity stage'!A$3:D$13,3,0) -> Other | M16: 0.25 | N16: 45992 | O16: Low | P16: =40000*5 -> 200000 | Q16: 4500 | R16: =Q16/$R$2 -> 53.437834 | S16: =(P16*R16)/1000000 -> 10.687567 | U16: Y
A17: 14 | B17: MSIL (4W) | C17: Roof speaker | D17: MPC | E17: Sound | F17: Spks. | G17: Line-fit | H17: Ashish | I17: Rachit | J17: O (L) | K17: =VLOOKUP(J17,'Opportunity stage'!A$3:D$13,2,0) -> Lost | L17: =VLOOKUP(J17,'Opportunity stage'!A$3:D$13,3,0) -> Other | M17: =VLOOKUP(J17,'Opportunity stage'!A$3:D$13,4,0) -> 0 | N17: 46082 | O17: Low | P17: =50000*5 -> 250000 | Q17: 300 | R17: =Q17/$R$2 -> 3.5625223 | S17: =(P17*R17)/1000000 -> 0.89063057 | U17: Y
A18: 15 | B18: Renault (4W) | C18: 12.3" IVI | D18: MPC | E18: IVI | F18: IVI | G18: Line-fit | H18: Gaurav | I18: Haseeb | J18: O (L) | K18: =VLOOKUP(J18,'Opportunity stage'!A$3:D$13,2,0) -> Lost | L18: =VLOOKUP(J18,'Opportunity stage'!A$3:D$13,3,0) -> Other | M18: =VLOOKUP(J18,'Opportunity stage'!A$3:D$13,4,0) -> 0 | N18: 46082 | O18: Low | P18: 100000 | Q18: 20000 | R18: =Q18/$R$2 -> 237.50148 | S18: =(P18*R18)/1000000 -> 23.750148 | T18: IVI awarded to Visteon | U18: Y
A19: 16 | B19: Renault (4W) | C19: 360-deg. camera solution | D19: MAC | E19: Smartcam | F19: 360-deg. camera | G19: Line-fit | H19: Gaurav | I19: Haseeb | J19: O (L) | K19: =VLOOKUP(J19,'Opportunity stage'!A$3:D$13,2,0) -> Lost | L19: =VLOOKUP(J19,'Opportunity stage'!A$3:D$13,3,0) -> Other | M19: =VLOOKUP(J19,'Opportunity stage'!A$3:D$13,4,0) -> 0 | N19: 46082 | O19: Low | P19: 150000 | Q19: 14350 | R19: =Q19/$R$2 -> 170.40732 | S19: =(P19*R19)/1000000 -> 25.561097 | T19: Renault’s expectations included execution of at least one prior vehicle fitment program by Pioneer, and the SOP timeline of 2026 also contributed to their decision | U19: N
A20: 17 | B20: Renault (4W) | C20: Wireless Charger Qi2.2 | D20: MAC | E20: Other MAC | F20: WLC | G20: Line-fit | H20: Gaurav | I20: Haseeb | J20: E | K20: =VLOOKUP(J20,'Opportunity stage'!A$3:D$13,2,0) -> RFQ | L20: =VLOOKUP(J20,'Opportunity stage'!A$3:D$13,3,0) -> Opportunity | M20: =VLOOKUP(J20,'Opportunity stage'!A$3:D$13,4,0) -> 0.5 | N20: 46357 | O20: Low | P20: =100000*4 -> 400000 | Q20: 2200 | R20: =Q20/$R$2 -> 26.125163 | S20: =(P20*R20)/1000000 -> 10.450065 | T20: Technical proposal under preparation | U20: N
A21: 18 | B21: Renault (4W) | C21: 6.5" Commodity speaker - SWEET platform | D21: MPC | E21: Sound | F21: Spks. | G21: Line-fit | H21: Gaurav | I21: Rachit | J21: O (L) | K21: =VLOOKUP(J21,'Opportunity stage'!A$3:D$13,2,0) -> Lost | L21: =VLOOKUP(J21,'Opportunity stage'!A$3:D$13,3,0) -> Other | M21: =VLOOKUP(J21,'Opportunity stage'!A$3:D$13,4,0) -> 0 | N21: Lost | O21: Low | P21: =120000*5 -> 600000 | Q21: 300 | R21: =Q21/$R$2 -> 3.5625223 | S21: =(P21*R21)/1000000 -> 2.1375134 | U21: Y
A22: 19 | B22: Renault (4W) | C22: 4.5" Commodity speaker - Kwid | D22: MPC | E22: Sound | F22: Spks. | G22: Line-fit | H22: Gaurav | I22: Rachit | J22: O (L) | K22: =VLOOKUP(J22,'Opportunity stage'!A$3:D$13,2,0) -> Lost | L22: =VLOOKUP(J22,'Opportunity stage'!A$3:D$13,3,0) -> Other | M22: =VLOOKUP(J22,'Opportunity stage'!A$3:D$13,4,0) -> 0 | N22: Lost | O22: Low | P22: 1500000 | Q22: 116 | R22: =Q22/$R$2 -> 1.3775086 | S22: =(P22*R22)/1000000 -> 2.0662629 | U22: N
A23: 20 | B23: Renault (4W) | C23: 6.5" Commodity speaker - Kiger, Triber | D23: MPC | E23: Sound | F23: Spks. | G23: Line-fit | H23: Gaurav | I23: Rachit | J23: O (L) | K23: =VLOOKUP(J23,'Opportunity stage'!A$3:D$13,2,0) -> Lost | L23: =VLOOKUP(J23,'Opportunity stage'!A$3:D$13,3,0) -> Other | M23: =VLOOKUP(J23,'Opportunity stage'!A$3:D$13,4,0) -> 0 | N23: Lost | O23: Low | P23: 1500000 | Q23: 138 | R23: =Q23/$R$2 -> 1.6387602 | S23: =(P23*R23)/1000000 -> 2.4581404 | U23: Y
A24: 21 | B24: Nissan (4W) | C24: 12.3" CDC | D24: MPC | E24: IVI | F24: CDC | G24: Line-fit | H24: Gaurav | I24: Haseeb | J24: C | K24: =VLOOKUP(J24,'Opportunity stage'!A$3:D$13,2,0) -> Lead | L24: =VLOOKUP(J24,'Opportunity stage'!A$3:D$13,3,0) -> Lead Qualification | M24: =VLOOKUP(J24,'Opportunity stage'!A$3:D$13,4,0) -> 0.5 | N24: 46447 | O24: Low | P24: =127000*5 -> 635000 | Q24: 28000 | R24: =Q24/$R$2 -> 332.50208 | S24: =(P24*R24)/1000000 -> 211.13882 | T24: Awaiting direction from Nissan for RFQ | U24: Y
A25: 22 | B25: Stellantis (4W) | C25: 6.5" speaker (Export market) | D25: MPC | E25: Sound | F25: Spks. | G25: Line-fit | H25: Gaurav | I25: Rachit | J25: O (D) | K25: =VLOOKUP(J25,'Opportunity stage'!A$3:D$13,2,0) -> Dropped | L25: =VLOOKUP(J25,'Opportunity stage'!A$3:D$13,3,0) -> Other | M25: =VLOOKUP(J25,'Opportunity stage'!A$3:D$13,4,0) -> 0 | N25: Dropped | O25: Low | P25: 545000 | Q25: 170 | R25: =Q25/$R$2 -> 2.0187626 | S25: =(P25*R25)/1000000 -> 1.1002256 | T25: No response from Stellantis | U25: N
A26: 23 | B26: Stellantis (4W) | C26: 360-deg. camera solution | D26: MAC | E26: Smartcam | F26: 360-deg. camera | G26: Line-fit | H26: Gaurav | I26: Haseeb | J26: SECURED | K26: =VLOOKUP(J26,'Opportunity stage'!A$3:D$13,2,0) -> Win | L26: =VLOOKUP(J26,'Opportunity stage'!A$3:D$13,3,0) -> Closing | M26: =VLOOKUP(J26,'Opportunity stage'!A$3:D$13,4,0) -> 1 | N26: Secured | O26: Secured | P26: 22800 | Q26: 14350 | R26: =Q26/$R$2 -> 170.40732 | S26: =(P26*R26)/1000000 -> 3.8852868 | U26: N
A27: 24 | B27: FIAT | C27: 360 Camera | D27: MAC | E27: Smartcam | F27: 360-deg. camera | G27: End-of-Line | H27: KG/PA | I27: Haseeb | J27: D | K27: =VLOOKUP(J27,'Opportunity stage'!A$3:D$13,2,0) -> Lead | L27: =VLOOKUP(J27,'Opportunity stage'!A$3:D$13,3,0) -> Supplier Qualification | M27: =VLOOKUP(J27,'Opportunity stage'!A$3:D$13,4,0) -> 0.5 | N27: 46266 | O27: Low | P27: 9000 | Q27: 25000 | R27: =Q27/$R$2 -> 296.87686 | S27: =(P27*R27)/1000000 -> 2.6718917 | T27: Discussion in progress with Stellantis Engg. team | U27: N
A28: 25 | B28: Tata CV (CV) | C28: Infotainment | D28: MPC | E28: IVI | F28: IVI | G28: Line-fit | H28: Parvez | I28: Haseeb | J28: O (D) | K28: =VLOOKUP(J28,'Opportunity stage'!A$3:D$13,2,0) -> Dropped | L28: =VLOOKUP(J28,'Opportunity stage'!A$3:D$13,3,0) -> Other | M28: =VLOOKUP(J28,'Opportunity stage'!A$3:D$13,4,0) -> 0 | N28: 45992 | O28: Dropped | P28: 6000 | Q28: 25000 | R28: =Q28/$R$2 -> 296.87686 | S28: =(P28*R28)/1000000 -> 1.7812611 | T28: Tata is not ready to handle MAP Topic, Due to its complexity and less volume Pioneer dropped this Project | U28: Y
A29: 26 | B29: Tata CV (CV) | C29: DMS | D29: MAC | E29: Other MAC | F29: DMS | G29: Line-fit | H29: Parvez | I29: Haseeb | J29: O (L) | K29: RFQ | L29: Lost | M29: Lost | N29: 45962 | O29: Lost | P29: 500000 | Q29: 3800 | R29: =Q29/$R$2 -> 45.125282 | S29: =(P29*R29)/1000000 -> 22.562641 | T29: Lost to (Novus Hi-Tech).
A30: 27 | B30: Hyundai | C30: 360-deg. camera solution | D30: MAC | E30: Smartcam | F30: 360-deg. camera | G30: Line-fit | H30: Gaurav | I30: Haseeb | J30: A | K30: =VLOOKUP(J30,'Opportunity stage'!A$3:D$13,2,0) -> Before Lead | L30: =VLOOKUP(J30,'Opportunity stage'!A$3:D$13,3,0) -> Planning | M30: =VLOOKUP(J30,'Opportunity stage'!A$3:D$13,4,0) -> 0 | N30: TBC | O30: Low | P30: 0 | Q30: 0 | R30: =Q30/$R$2 -> 0 | S30: =(P30*R30)/1000000 -> 0 | U30: N
A31: 28 | B31: VW / Skoda (4W) | C31: 360-deg. camera solution | D31: MAC | E31: Smartcam | F31: 360-deg. camera | G31: DOP | H31: Parvez | I31: Haseeb | J31: O (D) | K31: =VLOOKUP(J31,'Opportunity stage'!A$3:D$13,2,0) -> Dropped | L31: =VLOOKUP(J31,'Opportunity stage'!A$3:D$13,3,0) -> Other | M31: =VLOOKUP(J31,'Opportunity stage'!A$3:D$13,4,0) -> 0 | N31: 45992 | O31: Dropped | P31: 8000 | Q31: 13500 | R31: =Q31/$R$2 -> 160.3135 | S31: =(P31*R31)/1000000 -> 1.282508 | T31: We were not getting desired volume, Meantime Price of 360 degree increase due to technology shift from single chanel to dual chanel. | U31: N
A32: 29 | B32: VW / Skoda (4W) | C32: Dashcam (520DC) | D32: MAC | E32: Smartcam | F32: Dashcam | G32: DOP | H32: Parvez | I32: Haseeb | J32: O (D) | K32: =VLOOKUP(J32,'Opportunity stage'!A$3:D$13,2,0) -> Dropped | L32: =VLOOKUP(J32,'Opportunity stage'!A$3:D$13,3,0) -> Other | M32: =VLOOKUP(J32,'Opportunity stage'!A$3:D$13,4,0) -> 0 | N32: 45992 | O32: Dropped | P32: 8000 | Q32: 5000 | R32: =Q32/$R$2 -> 59.375371 | S32: =(P32*R32)/1000000 -> 0.47500297 | T32: Less intrest from SAVW side. | U32: N
A33: 30 | B33: Eicher/Volvo (CV) | C33: IVI | D33: MPC | E33: IVI | F33: IVI | G33: Line-fit | H33: Parvez | I33: Haseeb | J33: O (D) | K33: Lost | L33: Lost | M33: Lost | N33: 45931 | O33: Dropped | P33: 100000 | Q33: 14000 | R33: =Q33/$R$2 -> 166.25104 | S33: =(P33*R33)/1000000 -> 16.625104 | T33: VECV Was looking for engineering service and IVI development they wanted to develop with another source. | V33: Dropped by Pioneer.
A34: 31 | B34: Eicher/Volvo (CV) | C34: Wirless Charger MPP Profile Qi 2.2 | D34: MAC | E34: Other MAC | F34: WLC | G34: Line-fit | H34: Parvez | I34: Haseeb | J34: E | K34: =VLOOKUP(J34,'Opportunity stage'!A$3:D$13,2,0) -> RFQ | L34: =VLOOKUP(J34,'Opportunity stage'!A$3:D$13,3,0) -> Opportunity | M34: =VLOOKUP(J34,'Opportunity stage'!A$3:D$13,4,0) -> 0.5 | N34: 46174 | O34: Mid | P34: 100000 | Q34: 2500 | R34: =Q34/$R$2 -> 29.687686 | S34: =(P34*R34)/1000000 -> 2.9687686 | T34: RFQ received (28-Dec-2025) | U34: N
A35: 32 | B35: VW / Skoda (4W) | C35: Infotainment | D35: MPC | E35: IVI | F35: IVI | G35: DOP | H35: Parvez | I35: Haseeb | J35: O (D) | K35: =VLOOKUP(J35,'Opportunity stage'!A$3:D$13,2,0) -> Dropped | L35: =VLOOKUP(J35,'Opportunity stage'!A$3:D$13,3,0) -> Other | M35: =VLOOKUP(J35,'Opportunity stage'!A$3:D$13,4,0) -> 0 | N35: 45931 | O35: Dropped | P35: 20000 | Q35: 13000 | R35: =Q35/$R$2 -> 154.37596 | S35: =(P35*R35)/1000000 -> 3.0875193 | T35: RFQ Received, Commercial offer submitted. SAVW expectation is 12000 Against our Quote of 14500 INR | U35: N | V35: AFT product base proposed
A36: 33 | B36: Nissan (4W) | C36: Tweeter | D36: MPC | E36: Sound | F36: Spks. | G36: Line-fit | H36: Gaurav | I36: Rachit | J36: O (L) | K36: =VLOOKUP(J36,'Opportunity stage'!A$3:D$13,2,0) -> Lost | L36: =VLOOKUP(J36,'Opportunity stage'!A$3:D$13,3,0) -> Other | M36: =VLOOKUP(J36,'Opportunity stage'!A$3:D$13,4,0) -> 0 | N36: Lost | O36: Mid | P36: =127000*5 -> 635000 | Q36: 130 | R36: =Q36/$R$2 -> 1.5437596 | S36: =(P36*R36)/1000000 -> 0.98028738
A37: 34 | B37: Nissan (4W) | C37: Wirless Charger MPP Profile Qi 2.1 | D37: MAC | E37: Other MAC | F37: WLC | G37: Line-fit | H37: Gaurav | I37: Haseeb | J37: C | K37: =VLOOKUP(J37,'Opportunity stage'!A$3:D$13,2,0) -> Lead | L37: =VLOOKUP(J37,'Opportunity stage'!A$3:D$13,3,0) -> Lead Qualification | M37: =VLOOKUP(J37,'Opportunity stage'!A$3:D$13,4,0) -> 0.5 | N37: 46447 | O37: Mid | P37: =127000*5 -> 635000 | Q37: 1900 | R37: =Q37/$R$2 -> 22.562641 | S37: =(P37*R37)/1000000 -> 14.327277 | T37: Awaiting RFQ from Nissan
A38: 35 | B38: Nissan (4W) | C38: USB Port - Type A/C (60W + 20W) | D38: MAC | E38: Other MAC | F38: USB port | G38: Line-fit | H38: Gaurav | I38: Haseeb | J38: C | K38: =VLOOKUP(J38,'Opportunity stage'!A$3:D$13,2,0) -> Lead | L38: =VLOOKUP(J38,'Opportunity stage'!A$3:D$13,3,0) -> Lead Qualification | M38: =VLOOKUP(J38,'Opportunity stage'!A$3:D$13,4,0) -> 0.5 | N38: 46447 | O38: Mid | P38: =127000*5 -> 635000 | Q38: 500 | R38: =Q38/$R$2 -> 5.9375371 | S38: =(P38*R38)/1000000 -> 3.7703361 | T38: Awaiting RFQ from Nissan
A39: 36 | B39: Mahindra (4W) | C39: IRVM - with DVR | D39: MAC | E39: Smartcam | F39: Digital mirror | G39: Line-fit | H39: Gaurav | I39: Haseeb | J39: F | K39: =VLOOKUP(J39,'Opportunity stage'!A$3:D$13,2,0) -> RFQ | L39: =VLOOKUP(J39,'Opportunity stage'!A$3:D$13,3,0) -> Negotiation | M39: =VLOOKUP(J39,'Opportunity stage'!A$3:D$13,4,0) -> 0.75 | N39: 46082 | O39: Low | P39: 377000 | Q39: 16000 | R39: =Q39/$R$2 -> 190.00119 | S39: =(P39*R39)/1000000 -> 71.630448 | T39: TSO signed. Commercial negotiations to begin soon.
A40: 37 | B40: Renault (4W) | C40: 1" Tweeter - Special Edition Kiger/Triber | D40: MPC | E40: Sound | F40: Spks. | G40: Line-fit | H40: Gaurav | I40: Rachit | J40: O (L) | K40: =VLOOKUP(J40,'Opportunity stage'!A$3:D$13,2,0) -> Lost | L40: =VLOOKUP(J40,'Opportunity stage'!A$3:D$13,3,0) -> Other | M40: =VLOOKUP(J40,'Opportunity stage'!A$3:D$13,4,0) -> 0 | N40: Lost | O40: High | P40: =100000*5 -> 500000 | Q40: 130 | R40: =Q40/$R$2 -> 1.5437596 | S40: =(P40*R40)/1000000 -> 0.77187982
...

Sheet Category wise
A2: Deal stage | B2: (Multiple Items)
A4: Sum of TCV (USD Mln.) | B4: Column Labels
A5: Row Labels | B5: IVI | C5: Smartcam | D5: Sound | E5: Other MAC | F5: Grand Total
A6: Mahindra (4W) | B6: 0 | C6: 153.58033 | D6: 183.66888 | E6: 60.957131 | F6: 398.20634
A7: Nissan (4W) | B7: 211.13882 | C7: 0 | D7: 0.98028738 | E7: 18.097613 | F7: 230.21672
A8: MSIL (4W) | B8: 106.87567 | C8: 34.770217 | D8: 21.67201 | E8: 0 | F8: 163.3179
A9: Renault (4W) | B9: 23.750148 | C9: 25.561097 | D9: 12.171951 | E9: 10.450065 | F9: 71.933262
A10: Tata CV (CV) | B10: 0 | C10: 0 | D10: 0 | E10: 22.562641 | F10: 22.562641
A11: MG Motor (4W) | B11: 0 | C11: 14.250089 | D11: 0 | E11: 0 | F11: 14.250089
A12: Stellantis (4W) | B12: 0 | C12: 3.8852868 | D12: 0 | E12: 5.2369077 | F12: 9.1221945
A13: Tata PV (4W) | B13: 4.7500297 | C13: 0 | D13: 0 | E13: 0 | F13: 4.7500297
A14: Eicher/Volvo (CV) | B14: 0 | C14: 0 | D14: 0 | E14: 2.9687686 | F14: 2.9687686
A15: FIAT | B15: 0 | C15: 2.6718917 | D15: 0 | E15: 0 | F15: 2.6718917
A16: Daimler (CV) | B16: 0 | C16: 0.62047263 | D16: 0 | E16: 0 | F16: 0.62047263
A17: Force Motors (CV) | B17: 0.22800143 | C17: 0 | D17: 0.35625223 | E17: 0 | F17: 0.58425365
... A20: Grand Total | B20: 346.74267 | C20: 235.33939 | D20: 218.84938 | E20: 120.27313 | F20: 921.20456

Sheet Subcategory wise
A2: Deal stage | B2: (Multiple Items)
A4: Sum of TCV (USD Mln.) | B4: Column Labels
A5: Row Labels | B5: CDC | C5: Digital mirror | D5: WLC | E5: Dashcam | F5: 360-deg. camera | G5: Spk + Amp | H5: IVI | I5: USB port | J5: RVC with Display | K5: Spks. | L5: RVC | M5: Grand Total
A6: Nissan (4W) | B6: 211.13882 | C6: 0 | D6: 14.327277 | E6: 0 | F6: 0 | G6: 0 | H6: 0 | I6: 3.7703361 | J6: 0 | K6: 0 | L6: 0 | M6: 229.23643
A7: Mahindra (4W) | B7: 0 | C7: 153.58033 | D7: 59.969125 | E7: 0 | F7: 0 | G7: 7.4219214 | H7: 0 | I7: 0.98800618 | J7: 0 | K7: 0 | L7: 0 | M7: 221.95939
A8: MSIL (4W) | B8: 0 | C8: 0 | D8: 0 | E8: 34.770217 | F8: 0 | G8: 0 | H8: 0 | I8: 0 | J8: 0 | K8: 0 | L8: 0 | M8: 34.770217
A9: MG Motor (4W) | B9: 0 | C9: 0 | D9: 0 | E9: 0 | F9: 14.250089 | G9: 0 | H9: 0 | I9: 0 | J9: 0 | K9: 0 | L9: 0 | M9: 14.250089
A10: Renault (4W) | B10: 0 | C10: 0 | D10: 10.450065 | E10: 0 | F10: 0 | G10: 0 | H10: 0 | I10: 0 | J10: 0 | K10: 0 | L10: 0 | M10: 10.450065
A11: Stellantis (4W) | B11: 0 | C11: 0 | D11: 5.2369077 | E11: 0 | F11: 0 | G11: 0 | H11: 0 | I11: 0 | J11: 0 | K11: 0 | L11: 0 | M11: 5.2369077
A12: Tata PV (4W) | B12: 0 | C12: 0 | D12: 0 | E12: 0 | F12: 0 | G12: 0 | H12: 4.7500297 | I12: 0 | J12: 0 | K12: 0 | L12: 0 | M12: 4.7500297
A13: Eicher/Volvo (CV) | B13: 0 | C13: 0 | D13: 2.9687686 | E13: 0 | F13: 0 | G13: 0 | H13: 0 | I13: 0 | J13: 0 | K13: 0 | L13: 0 | M13: 2.9687686
A14: FIAT | B14: 0 | C14: 0 | D14: 0 | E14: 0 | F14: 2.6718917 | G14: 0 | H14: 0 | I14: 0 | J14: 0 | K14: 0 | L14: 0 | M14: 2.6718917
A15: Daimler (CV) | B15: 0 | C15: 0 | D15: 0 | E15: 0 | F15: 0 | G15: 0 | H15: 0 | I15: 0 | J15: 0.62047263 | K15: 0 | L15: 0 | M15: 0.62047263
A16: Force Motors (CV) | B16: 0 | C16: 0 | D16: 0 | E16: 0 | F16: 0 | G16: 0 | H16: 0.22800143 | I16: 0 | J16: 0 | K16: 0.35625223 | L16: 0 | M16: 0.58425365
A17: Hyundai | B17: 0 | C17: 0 | D17: 0 | E17: 0 | F17: 0 | G17: 0 | H17: 0 | I17: 0 | J17: 0 | K17: 0 | L17: 0 | M17: 0
... A19: Grand Total | B19: 211.13882 | C19: 153.58033 | D19: 92.952143 | E19: 34.770217 | F19: 16.921981 | G19: 7.4219214 | H19: 4.9780311 | I19: 4.7583422 | J19: 0.62047263 | K19: 0.35625223 | L19: 0 | M19: 527.49852

Sheet Confidence level
A2: Deal stage | B2: (Multiple Items)
A4: Sum of TCV (USD Mln.) | B4: Column Labels
A5: Row Labels | B5: Low | C5: Lost | D5: Mid | E5: High | F5: Secured | G5: Grand Total
A6: CDC | B6: 211.13882 | C6: 0 | D6: 0 | E6: 0 | F6: 0 | G6: 211.13882
A7: Spk + Amp | B7: 86.946396 | C7: 96.72248 | D7: 0 | E7: 0 | F7: 0 | G7: 183.66888
A8: Digital mirror | B8: 153.58033 | C8: 0 | D8: 0 | E8: 0 | F8: 0 | G8: 153.58033
A9: DA | B9: 106.87567 | C9: 0 | D9: 0 | E9: 0 | F9: 0 | G9: 106.87567
A10: WLC | B10: 10.450065 | C10: 0 | D10: 59.939437 | E10: 22.562641 | F10: 0 | G10: 92.952143
A11: 360-deg. camera | B11: 28.232989 | C11: 0 | D11: 14.250089 | E11: 0 | F11: 3.8852868 | G11: 46.368365
A12: Spks. | B12: 33.072082 | C12: 0 | D12: 1.3365396 | E12: 0.77187982 | F12: 0 | G12: 35.180501
A13: Dashcam | B13: 0 | C13: 0 | D13: 34.770217 | E13: 0 | F13: 0 | G13: 34.770217
A14: IVI | B14: 28.500178 | C14: 0 | D14: 0.22800143 | E14: 0 | F14: 0 | G14: 28.72818
A15: DMS | B15: 0 | C15: 22.562641 | D15: 0 | E15: 0 | F15: 0 | G15: 22.562641
A16: USB port | B16: 0.98800618 | C16: 0 | D16: 3.7703361 | E16: 0 | F16: 0 | G16: 4.7583422
A17: RVC with Display | B17: 0 | C17: 0 | D17: 0.62047263 | E17: 0 | F17: 0 | G17: 0.62047263
... A19: Grand Total | B19: 659.78454 | C19: 119.28512 | D19: 114.91509 | E19: 23.334521 | F19: 3.8852868 | G19: 921.20456

Sheet BU wise
A2: Deal stage | B2: (Multiple Items)
A4: Sum of TCV (USD Mln.) | B4: Column Labels
A5: Row Labels | B5: Low | C5: Lost | D5: Mid | E5: High | F5: Secured | G5: Grand Total
A6: MPC | B6: 466.53314 | C6: 96.72248 | D6: 1.564541 | E6: 0.77187982 | F6: 0 | G6: 565.59204
A7: MAC | B7: 193.2514 | C7: 22.562641 | D7: 113.35055 | E7: 22.562641 | F7: 3.8852868 | G7: 355.61252
A8: Grand Total | B8: 659.78454 | C8: 119.28512 | D8: 114.91509 | E8: 23.334521 | F8: 3.8852868 | G8: 921.20456

Sheet Stage wise
A4: Sum of TCV (USD Mln.) | B4: Column Labels
A5: Row Labels | B5: Low | C5: Lost | D5: Mid | E5: High | F5: Secured | G5: Grand Total
A6: O (L) | B6: 268.78347 | C6: 119.28512 | D6: 0.98028738 | E6: 0.77187982 | F6: 0 | G6: 389.82076
A7: C | B7: 211.13882 | C7: 0 | D7: 23.334521 | E7: 0 | F7: 0 | G7: 234.47334
A8: F | B8: 129.83019 | C8: 0 | D8: 37.990737 | E8: 0 | F8: 0 | G8: 167.82092
A9: E | B9: 10.450065 | C9: 0 | D9: 17.83933 | E9: 22.562641 | F9: 0 | G9: 50.852037
A10: D | B10: 10.093813 | C10: 0 | D10: 34.770217 | E10: 0 | F10: 0 | G10: 44.86403
A11: A | B11: 28.500178 | C11: 0 | D11: 0 | E11: 0 | F11: 0 | G11: 28.500178
A12: SECURED | B12: 0 | C12: 0 | D12: 0 | E12: 0 | F12: 3.8852868 | G12: 3.8852868
A13: B | B13: 0.98800618 | C13: 0 | D13: 0 | E13: 0 | F13: 0 | G13: 0.98800618
A14: Grand Total | B14: 659.78454 | C14: 119.28512 | D14: 114.91509 | E14: 23.334521 | F14: 3.8852868 | G14: 921.20456

Sheet Customer wise
A4: Sum of TCV (USD Mln.) | B4: Column Labels
A5: Row Labels | B5: O (L) | C5: C | D5: F | E5: E | F5: D | G5: A | H5: SECURED | I5: B | J5: Grand Total
A6: Mahindra (4W) | B6: 176.24695 | C6: 0 | D6: 167.23667 | E6: 22.562641 | F6: 7.4219214 | G6: 23.750148 | H6: 0 | I6: 0.98800618 | J6: 398.20634
A7: Nissan (4W) | B7: 0.98028738 | C7: 229.23643 | D7: 0 | E7: 0 | F7: 0 | G7: 0 | H7: 0 | I7: 0 | J7: 230.21672
A8: MSIL (4W) | B8: 128.54768 | C8: 0 | D8: 0 | E8: 0 | F8: 34.770217 | G8: 0 | H8: 0 | I8: 0 | J8: 163.3179
A9: Renault (4W) | B9: 61.483197 | C9: 0 | D9: 0 | E9: 10.450065 | F9: 0 | G9: 0 | H9: 0 | I9: 0 | J9: 71.933262
A10: Tata CV (CV) | B10: 22.562641 | C10: 0 | D10: 0 | E10: 0 | F10: 0 | G10: 0 | H10: 0 | I10: 0 | J10: 22.562641
A11: MG Motor (4W) | B11: 0 | C11: 0 | D11: 0 | E11: 14.250089 | F11: 0 | G11: 0 | H11: 0 | I11: 0 | J11: 14.250089
A12: Stellantis (4W) | B12: 0 | C12: 5.2369077 | D12: 0 | E12: 0 | F12: 0 | G12: 0 | H12: 3.8852868 | I12: 0 | J12: 9.1221945
A13: Tata PV (4W) | B13: 0 | C13: 0 | D13: 0 | E13: 0 | F13: 0 | G13: 4.7500297 | H13: 0 | I13: 0 | J13: 4.7500297
A14: Eicher/Volvo (CV) | B14: 0 | C14: 0 | D14: 0 | E14: 2.9687686 | F14: 0 | G14: 0 | H14: 0 | I14: 0 | J14: 2.9687686
A15: FIAT | B15: 0 | C15: 0 | D15: 0 | E15: 0 | F15: 2.6718917 | G15: 0 | H15: 0 | I15: 0 | J15: 2.6718917
A16: Daimler (CV) | B16: 0 | C16: 0 | D16: 0 | E16: 0.62047263 | F16: 0 | G16: 0 | H16: 0 | I16: 0 | J16: 0.62047263
A17: Force Motors (CV) | B17: 0 | C17: 0 | D17: 0.58425365 | E17: 0 | F17: 0 | G17: 0 | H17: 0 | I17: 0 | J17: 0.58425365
... A20: Grand Total | B20: 389.82076 | C20: 234.47334 | D20: 167.82092 | E20: 50.852037 | F20: 44.86403 | G20: 28.500178 | H20: 3.8852868 | I20: 0.98800618 | J20: 921.20456

Sheet Team members
A2: Sum of TCV (USD Mln.) | B2: Column Labels
A3: Row Labels | B3: O (L) | C3: C | D3: F | E3: E | F3: D | G3: A | H3: SECURED | I3: B | J3: Grand Total
A4: Gaurav | B4: 62.463484 | C4: 234.47334 | D4: 167.23667 | E4: 47.883268 | F4: 0 | G4: 23.750148 | H4: 3.8852868 | I4: 0.98800618 | J4: 540.6802
A5: Parvez | B5: 198.8096 | C5: 0 | D5: 0.58425365 | E5: 2.9687686 | F5: 7.4219214 | G5: 4.7500297 | H5: 0 | I5: 0 | J5: 214.53457
A6: Ashish | B6: 128.54768 | C6: 0 | D6: 0 | E6: 0 | F6: 34.770217 | G6: 0 | H6: 0 | I6: 0 | J6: 163.3179
A7: KG/PA | B7: 0 | C7: 0 | D7: 0 | E7: 0 | F7: 2.6718917 | G7: 0 | H7: 0 | I7: 0 | J7: 2.6718917
A8: Grand Total | B8: 389.82076 | C8: 234.47334 | D8: 167.82092 | E8: 50.852037 | F8: 44.86403 | G8: 28.500178 | H8: 3.8852868 | I8: 0.98800618 | J8: 921.20456
A10: Sum of TCV (USD Mln.) | B10: Column Labels
A11: Row Labels | B11: O (L) | C11: C | D11: F | E11: E | F11: D | G11: A | H11: SECURED | I11: B | J11: Grand Total
A12: Haseeb | B12: 71.873887 | C12: 234.47334 | D12: 167.23667 | E12: 50.852037 | F12: 2.6718917 | G12: 28.500178 | H12: 3.8852868 | I12: 0.98800618 | J12: 560.4813
A13: Rachit | B13: 317.94687 | C13: 0 | D13: 0.58425365 | E13: 0 | F13: 42.192139 | G13: 0 | H13: 0 | I13: 0 | J13: 360.72326
A14: Grand Total | B14: 389.82076 | C14: 234.47334 | D14: 167.82092 | E14: 50.852037 | F14: 44.86403 | G14: 28.500178 | H14: 3.8852868 | I14: 0.98800618 | J14: 921.20456

Sheet Opportunity count
A4: Count of Description | B4: Column Labels
A5: Row Labels | B5: A | C5: B | D5: C | E5: D | F5: E | G5: F | H5: O (L) | I5: SECURED | J5: Grand Total
A6: FIAT | B6: 0 | C6: 0 | D6: 0 | E6: 1 | F6: 0 | G6: 0 | H6: 0 | I6: 0 | J6: 1
A7: Hyundai | B7: 1 | C7: 0 | D7: 0 | E7: 0 | F7: 0 | G7: 0 | H7: 0 | I7: 0 | J7: 1
A8: Mahindra (4W) | B8: 1 | C8: 1 | D8: 0 | E8: 1 | F8: 1 | G8: 3 | H8: 3 | I8: 0 | J8: 10
A9: MSIL (4W) | B9: 0 | C9: 0 | D9: 0 | E9: 1 | F9: 0 | G9: 0 | H9: 4 | I9: 0 | J9: 5
A10: Nissan (4W) | B10: 0 | C10: 0 | D10: 3 | E10: 0 | F10: 0 | G10: 0 | H10: 1 | I10: 0 | J10: 4
A11: Renault (4W) | B11: 0 | C11: 0 | D11: 0 | E11: 0 | F11: 1 | G11: 0 | H11: 7 | I11: 0 | J11: 8
A12: Stellantis (4W) | B12: 0 | C12: 0 | D12: 1 | E12: 0 | F12: 0 | G12: 0 | H12: 0 | I12: 1 | J12: 2
A13: Tata CV (CV) | B13: 0 | C13: 0 | D13: 0 | E13: 0 | F13: 0 | G13: 0 | H13: 1 | I13: 0 | J13: 1
A14: Eicher/Volvo (CV) | B14: 0 | C14: 0 | D14: 0 | E14: 0 | F14: 1 | G14: 0 | H14: 0 | I14: 0 | J14: 1
A15: Daimler (CV) | B15: 0 | C15: 0 | D15: 0 | E15: 0 | F15: 1 | G15: 0 | H15: 0 | I15: 0 | J15: 1
A16: Force Motors (CV) | B16: 0 | C16: 0 | D16: 0 | E16: 0 | F16: 0 | G16: 2 | H16: 0 | I16: 0 | J16: 2
A17: Tata PV (4W) | B17: 1 | C17: 0 | D17: 0 | E17: 0 | F17: 0 | G17: 0 | H17: 0 | I17: 0 | J17: 1
... A20: Grand Total | B20: 5 | C20: 1 | D20: 4 | E20: 3 | F20: 5 | G20: 5 | H20: 16 | I20: 1 | J20: 40

Sheet Customer wise (2)
A4: Sum of TCV (USD Mln.) | B4: Column Labels
A5: Row Labels | B5: A | C5: B | D5: C | E5: D | F5: E | G5: F | H5: Grand Total
A6: IVI | B6: 4.7500297 | C6: 0 | D6: 211.13882 | E6: 0 | F6: 0 | G6: 0.22800143 | H6: 216.11685
A7: Smartcam | B7: 23.750148 | C7: 0 | D7: 0 | E7: 37.442109 | F7: 14.870562 | G7: 129.83019 | H7: 205.89301
A8: Other MAC | B8: 0 | C8: 0.98800618 | D8: 23.334521 | E8: 0 | F8: 35.981475 | G8: 37.406484 | H8: 97.710486
A9: Sound | B9: 0 | C9: 0 | D9: 0 | E9: 7.4219214 | F9: 0 | G9: 0.35625223 | H9: 7.7781736
A10: Grand Total | B10: 28.500178 | C10: 0.98800618 | D10: 234.47334 | E10: 44.86403 | F10: 50.852037 | G10: 167.82092 | H10: 527.49852

Sheet Subcategory wise (2)
A2: Deal stage | B2: (Multiple Items)
A4: Sum of TCV (USD Mln.) | B4: Column Labels
A5: Row Labels | B5: MAC | C5: MPC | D5: Grand Total
A6: Nissan (4W) | B6: 18.097613 | C6: 211.13882 | D6: 229.23643
A7: Mahindra (4W) | B7: 214.53747 | C7: 7.4219214 | D7: 221.95939
A8: MSIL (4W) | B8: 34.770217 | C8: 0 | D8: 34.770217
A9: MG Motor (4W) | B9: 14.250089 | C9: 0 | D9: 14.250089
A10: Renault (4W) | B10: 10.450065 | C10: 0 | D10: 10.450065
A11: Stellantis (4W) | B11: 5.2369077 | C11: 0 | D11: 5.2369077
A12: Tata PV (4W) | B12: 0 | C12: 4.7500297 | D12: 4.7500297
A13: Eicher/Volvo (CV) | B13: 2.9687686 | C13: 0 | D13: 2.9687686
A14: FIAT | B14: 2.6718917 | C14: 0 | D14: 2.6718917
A15: Daimler (CV) | B15: 0.62047263 | C15: 0 | D15: 0.62047263
A16: Force Motors (CV) | B16: 0 | C16: 0.58425365 | D16: 0.58425365
A17: Grand Total | B17: 303.60349 | C17: 223.89502 | D17: 527.49852
